Workbook

Sheet SOV
A1: BDE Florida, LLC
A2: 26-27 Statement of Values
A3: Loc No | B3: Store Location Number | C3: Address | D3: City | E3: State | F3: Zip | G3: County | H3: Occupancy Type | I3: Building Limit | J3: Contents Limit | K3: Signs Limit | L3: Business Income Limit | M3: Total Insured Values | N3: Projected Sales | O3: Drive Thru | P3: Year Built | Q3: Square Feet | R3: Const. Type | S3: No of Stories | T3: Sprinker | U3: Central Station Alarm | V3: Flood Zone | W3: PPC Code | X3: Distance to Water | Y3: Hours of Operation | Z3: Notes
A4: 1 | B4: 29576 | C4: 3401 5th Ave. N | D4: St. Petersburg | E4: FL | F4: 33713 | G4: Pinellas | H4: Restaurant | I4: 850000 | J4: 400000 | K4: 40000 | L4: 744931 | M4: =SUM(I4:L4) -> 2034931 | N4: 2102629 | O4: Y | P4: 1996 | Q4: 2780 | R4: Frame | S4: 1 | T4: N | U4: Y | V4: X | W4: 2 | X4: 5.1 Miles | Y4: 8am - 3am
A5: 2 | B5: 29577 | C5: 7329 W. Waters Ave. | D5: Tampa | E5: FL | F5: 33634 | G5: Hillsborough | H5: Restaurant | I5: 850000 | J5: 400000 | K5: 40000 | L5: 582831 | M5: =SUM(I5:L5) -> 1872831 | N5: 1645087 | O5: Y | P5: 1996 | Q5: 2182 | R5: Frame | S5: 1 | T5: N | U5: Y | V5: X | W5: 3 | X5: 4.6 Miles | Y5: 9am-1am
A6: 3 | B6: 29578 | C6: 5318 E. Fowler Ave. | D6: Tampa | E6: FL | F6: 33617 | G6: Hillsborough | H6: Restaurant | I6: 850000 | J6: 400000 | K6: 40000 | L6: 736943 | M6: =SUM(I6:L6) -> 2026943 | N6: 2080081 | O6: Y | P6: 1996 | Q6: 2599 | R6: JM | S6: 1 | T6: N | U6: Y | V6: X | W6: 1 | X6: 19 Miles | Y6: 9am-2am
A7: 4 | B7: 29579 | C7: 3600 4th St. N | D7: St. Petersburg | E7: FL | F7: 33704 | G7: Pinellas | H7: Restaurant | I7: 850000 | J7: 400000 | K7: 40000 | L7: 593437 | M7: =SUM(I7:L7) -> 1883437 | N7: 1675024 | O7: Y | P7: 1996 | Q7: 2304 | R7: Frame | S7: 1 | T7: N | U7: Y | V7: X | W7: 2 | X7: 9.1 Miles | Y7: 9am-1:30am
A8: 5 | B8: 29580 | C8: 904 Bloomingdale Rd. | D8: Brandon | E8: FL | F8: 33511 | G8: Hillsborough | H8: Restaurant | I8: 850000 | J8: 400000 | K8: 40000 | L8: 387177 | M8: =SUM(I8:L8) -> 1677177 | N8: 1092838 | O8: Y | P8: 1996 | Q8: 1944 | R8: JM | S8: 1 | T8: N | U8: Y | V8: X | W8: 3 | X8: 9.2 Miles | Y8: 9am-12am
A9: 6 | B9: 29581 | C9: 7313 Gall Blvd. | D9: Zephyrhills | E9: FL | F9: 33541 | G9: Pasco | H9: Restaurant | I9: 850000 | J9: 400000 | K9: 40000 | L9: 1047182 | M9: =SUM(I9:L9) -> 2337182 | N9: 2955757 | O9: Y | P9: 1997 | Q9: 1944 | R9: Frame | S9: 1 | T9: N | U9: Y | V9: X | W9: 3 | X9: 39.8 Miles | Y9: 7am-3am
A10: 7 | B10: 29582 | C10: 706 E. Martin Luther King Jr Blvd. W | D10: Seffner | E10: FL | F10: 33584 | G10: Hillsborough | H10: Restaurant | I10: 850000 | J10: 400000 | K10: 40000 | L10: 797398 | M10: =SUM(I10:L10) -> 2087398 | N10: 2250722 | O10: Y | P10: 1997 | Q10: 1980 | R10: JM | S10: 1 | T10: N | U10: Y | V10: X | W10: 3 | X10: 14.2 Miles | Y10: 9am-1am
A11: 8 | B11: 29583 | C11: 1701 E. Fowler Ave. | D11: Tampa | E11: FL | F11: 33612 | G11: Hillsborough | H11: Restaurant | I11: 850000 | J11: 400000 | K11: 40000 | L11: 442556 | M11: =SUM(I11:L11) -> 1732556 | N11: 1249150 | O11: Y | P11: 1999 | Q11: 2304 | R11: Frame | S11: 1 | T11: N | U11: Y | V11: X | W11: 3 | X11: 16.4 Miles | Y11: 9am-12am
A12: 9 | B12: 29584 | C12: 3802 S. Dale Mabry Hwy. | D12: Tampa | E12: FL | F12: 33611 | G12: Hillsborough | H12: Restaurant | I12: 850000 | J12: 400000 | K12: 40000 | L12: 742946 | M12: =SUM(I12:L12) -> 2032946 | N12: 2097026 | O12: Y | P12: 1999 | Q12: 2394 | R12: JM | S12: 1 | T12: N | U12: Y | V12: X | W12: 3 | X12: 8 Miles | Y12: 9am-2am
A13: 10 | B13: 29585 | C13: 3710 Cortez Rd. W | D13: Bradenton | E13: FL | F13: 34210 | G13: Manatee | H13: Restaurant | I13: 850000 | J13: 400000 | K13: 40000 | L13: 668152 | M13: =SUM(I13:L13) -> 1958152 | N13: 1885914 | O13: Y | P13: 2000 | Q13: 2166 | R13: JM | S13: 1 | T13: N | U13: Y | V13: X | W13: 3 | X13: 3.7 Miles | Y13: 9am-1am
A14: 11 | B14: 29586 | C14: 7620 W. Hillsborough Ave. | D14: Tampa | E14: FL | F14: 33615 | G14: Hillsborough | H14: Restaurant | I14: 850000 | J14: 400000 | K14: 40000 | L14: 474088 | M14: =SUM(I14:L14) -> 1764088 | N14: 1338151 | O14: Y | P14: 2000 | Q14: 2304 | R14: Frame | S14: 1 | T14: N | U14: Y | V14: X | W14: 3 | X14: 2.5 Miles | Y14: 9am-12am
A15: 12 | B15: 29587 | C15: 6004 14th St. | D15: Bradenton | E15: FL | F15: 34207 | G15: Manatee | H15: Restaurant | I15: 850000 | J15: 400000 | K15: 40000 | L15: 719164 | M15: =SUM(I15:L15) -> 2009164 | N15: 2029898 | O15: Y | P15: 2001 | Q15: 2060 | R15: JM | S15: 1 | T15: N | U15: Y | V15: X | W15: 3 | X15: 2.1 Miles | Y15: 9am-3am
A16: 13 | B16: 29588 | C16: 11315 Causeway Blvd. | D16: Brandon | E16: FL | F16: 33511 | G16: Hillsborough | H16: Restaurant | I16: 850000 | J16: 400000 | K16: 40000 | L16: 802618 | M16: =SUM(I16:L16) -> 2092618 | N16: 2265453 | O16: Y | P16: 2003 | Q16: 2062 | R16: JM | S16: 1 | T16: N | U16: Y | V16: X | W16: 3 | X16: 7.1 Miles | Y16: 9am-2:30am
A17: 14 | B17: 29589 | C17: 9211 US Hwy 19 N | D17: Port Richey | E17: FL | F17: 34668 | G17: Pasco | H17: Restaurant | I17: 850000 | J17: 400000 | K17: 40000 | L17: 422612 | M17: =SUM(I17:L17) -> 1712612 | N17: 1192856 | O17: Y | P17: 2005 | Q17: 2304 | R17: Frame | S17: 1 | T17: N | U17: Y | V17: AE | W17: 4 | X17: 12.1 Miles | Y17: 9am-11pm | Z17: NFIP Flood
A18: 15 | B18: 29590 | C18: 2442 Jim Redman Pkwy. | D18: Plant City | E18: FL | F18: 33566 | G18: Hillsborough | H18: Restaurant | I18: 850000 | J18: 400000 | K18: 40000 | L18: 718142 | M18: =SUM(I18:L18) -> 2008142 | N18: 2027013 | O18: Y | P18: 2005 | Q18: 2880 | R18: JM | S18: 1 | T18: N | U18: Y | V18: X | W18: 5 | X18: 29.6 Miles | Y18: 9am-2am
A19: 16 | B19: 29591 | C19: 640 10th St. E | D19: Palmetto | E19: FL | F19: 34221 | G19: Manatee | H19: Restaurant | I19: 850000 | J19: 400000 | K19: 40000 | L19: 496372 | M19: =SUM(I19:L19) -> 1786372 | N19: 1401049 | O19: Y | P19: 2005 | Q19: 3067 | R19: JM | S19: 1 | T19: N | U19: Y | V19: X | W19: 4 | X19: 2.0 Miles | Y19: 9am-12am
A20: 17 | B20: 29592 | C20: 12816 US Hwy 301 | D20: Dade City | E20: FL | F20: 33525 | G20: Pasco | H20: Restaurant | I20: 850000 | J20: 400000 | K20: 40000 | L20: 580418 | M20: =SUM(I20:L20) -> 1870418 | N20: 1638276 | O20: Y | P20: 2008 | Q20: 2787 | R20: Frame | S20: 1 | T20: N | U20: Y | V20: X | W20: 4 | X20: 33.1 Miles | Y20: 9am-1am
A21: 18 | B21: 29593 | C21: 9442 State Rd. 52 | D21: Hudson | E21: FL | F21: 34669 | G21: Pasco | H21: Restaurant | I21: 850000 | J21: 400000 | K21: 40000 | L21: 742110 | M21: =SUM(I21:L21) -> 2032110 | N21: 2094664 | O21: Y | P21: 2010 | Q21: 2855 | R21: Frame | S21: 1 | T21: N | U21: Y | V21: X | W21: 4 | X21: 3 Miles | Y21: 9am-2am
A22: 19 | B22: 29594 | C22: 11118 Bloomingdale Ave. | D22: Riverview | E22: FL | F22: 33578 | G22: Pasco | H22: Restaurant | I22: 850000 | J22: 400000 | K22: 40000 | L22: 428489 | M22: =SUM(I22:L22) -> 1718489 | N22: 1209444 | O22: Y | P22: 2012 | Q22: 2300 | R22: JM | S22: 1 | T22: N | U22: Y | V22: X | W22: 3 | X22: 8.8 Miles | Y22: 9am12am
A23: 20 | B23: 29595 | C23: 3803 W. Minnehaha St. | D23: Tampa | E23: FL | F23: 33614 | G23: Hillsborough | H23: Restaurant | I23: 850000 | J23: 400000 | K23: 40000 | L23: 587623 | M23: =SUM(I23:L23) -> 1877623 | N23: 1658613 | O23: Y | P23: 2012 | Q23: 2300 | R23: JM | S23: 1 | T23: N | U23: Y | V23: X | W23: 3 | X23: 6.4 Miles | Y23: 9am-1am
A24: 21 | B24: 30436 | C24: 903 Pasadena Ave. S | D24: South Pasadena | E24: FL | F24: 33707 | G24: Pinellas | H24: Restaurant | I24: 1441000 | J24: 400000 | K24: 40000 | L24: 427128 | M24: =SUM(I24:L24) -> 2308128 | N24: 1205604 | O24: Y | P24: 2014 | Q24: 2141 | R24: JM | S24: 1 | T24: N | U24: Y | V24: AE | W24: 4 | X24: 7.2 Miles | Y24: 9am-1am | Z24: NFIP Flood
A25: 22 | B25: 30370 | C25: 1495 4th St. S | D25: St. Petersburg | E25: FL | F25: 33701 | G25: Pinellas | H25: Restaurant | I25: 850000 | J25: 400000 | K25: 40000 | L25: 377617 | M25: =SUM(I25:L25) -> 1667617 | N25: 1065855 | O25: Y | P25: 2014 | Q25: 1935 | R25: JM | S25: 1 | T25: N | U25: Y | V25: AE | W25: 2 | X25: 6.6 Miles | Y25: 9am-11:30am | Z25: NFIP Flood
A26: 23 | B26: 31006 | C26: 31001 Cortez Blvd. | D26: Brooksville | E26: FL | F26: 34602 | G26: Hernando | H26: Restaurant | I26: 850000 | J26: 400000 | K26: 40000 | L26: 414363 | M26: =SUM(I26:L26) -> 1704363 | N26: 1169572 | O26: Y | P26: 2015 | Q26: 2200 | R26: JM | S26: 1 | T26: N | U26: Y | V26: X | W26: 2 | X26: 25.9 Miles | Y26: 9am-1am
A27: 24 | B27: 31597 | C27: 2575 E. Hillsborough Ave. | D27: Tampa | E27: FL | F27: 33610 | G27: Hillsborough | H27: Restaurant | I27: 850000 | J27: 400000 | K27: 40000 | L27: 474604 | M27: =SUM(I27:L27) -> 1764604 | N27: 1339608 | O27: Y | P27: 2015 | Q27: 2200 | R27: JM | S27: 1 | T27: N | U27: Y | V27: X | W27: 3 | X27: 4.5 Miles | Y27: 9am-12am
A28: 25 | B28: 32758 | C28: 8347 State Rd. 64 | D28: Bradenton | E28: FL | F28: 34212 | G28: Manatee | H28: Restaurant | I28: 850000 | J28: 400000 | K28: 40000 | L28: 594705 | M28: =SUM(I28:L28) -> 1884705 | N28: 1678603 | O28: Y | P28: 2017 | Q28: 2258 | R28: JM | S28: 1 | T28: N | U28: Y | V28: X | W28: 3 | X28: 7.58 Miles | Y28: 9am-12am
A29: 26 | B29: 34960 | C29: 15215 Garnett Trail | D29: Bradenton | E29: FL | F29: 34211 | G29: Manatee | H29: Restaurant | I29: 850000 | J29: 400000 | K29: 40000 | L29: 324554 | M29: =SUM(I29:L29) -> 1614554 | N29: 916079 | O29: Y | P29: 2018 | Q29: 3000 | R29: JM | S29: 1 | T29: Y | U29: Y | V29: X | W29: 2 | X29: 14.03 Miles | Y29: 9am-1am
A30: 27 | B30: 40715 | C30: 3824 US 301 S | D30: Riverview | E30: FL | F30: 33578 | G30: Pinellas | H30: Restaurant | I30: 850000 | J30: 400000 | K30: 40000 | L30: 525000 | M30: =SUM(I30:L30) -> 1815000 | N30: 1500000 | O30: Y | P30: 2011 | Q30: 2200 | R30: JM | S30: 1 | T30: Y | U30: N | X30: 12.5 Miles | Y30: 8am-3am
A31: Totals | I31: =SUM(I4:I30) -> 23541000 | J31: =SUM(J4:J30) -> 10800000 | K31: =SUM(K4:K30) -> 1080000 | L31: =SUM(L4:L30) -> 15853160 | M31: =SUM(M4:M30) -> 51274160 | N31: =SUM(N4:N30) -> 44764966

Sheet Setup
A1: GL RATE INDICATION — SETUP & ASSUMPTIONS
A3: ACCOUNT & POLICY INFORMATION
A4: Account Name | B4: BDE FLORIDA | C4: ← Green cells = required inputs
A5: Application ID
A6: GL Limit | B6: $1MM/$2MM
A7: Valuation Date of Loss Runs | B7: 46115
A8: Prospective Year Annual Sales ($) | B8: =SOV!N31 -> 44764966 | C8: =IFERROR("← enter " & TEXT(YEAR(B7)+IF(MONTH(B7)>=7,1,0),"0") & " revenue","← enter prospective year revenue") -> ← enter 2026 revenue
A9: Competing/Expiring Premium ($) | B9: 189000
A10: Deductible per Occurrence ($) | B10: 10000 | C10: ← Use dropdown for standard amounts ($0 / $5K / $10K / $25K / $50K / $100K), or type any whole-dollar amount
A11: LOSS DEVELOPMENT FACTORS
A12: LDF Source | B12: Everspan Fitted
A14: LOSS LIMIT SELECTION
A15: Selected Per-Occurrence Loss Limit | B15: $100K
A16: Capped / Uncapped Weighting (Capped %) | B16: 0.5
A17: CL / BF Blending Weight (CL %) | B17: 0.5
A19: ISO Excess Rate Table (per-occ limit → gross-up factor to unlimited)
A20: Loss Limit | B20: ISO XS Rate ($1M Occ. Limit) | C20: ISO XS Rate ($2M Occ. Limit) | D20: Source / Notes
A21: $100K | B21: 1.495 | C21: =IFERROR($B$25*B21,0) -> 1.65646 | D21: KB carrier filing; verify vs ISO CGL ELF (Hazard Group, Rule 56)
A22: $250K | C22: =IFERROR($B$25*B22,0) -> 0 | D22: Enter from ISO CGL ELF table — Hazard Group specific (ISO Circular LI-CF) | E22: =IF(AND(B22="",$B$15="$250K"),"⚠ Enter $250K XS rate above","")
A23: $500K | C23: =IFERROR($B$25*B23,0) -> 0 | D23: Enter from ISO CGL ELF table — Hazard Group specific (ISO Circular LI-CF) | E23: =IF(AND(B23="",$B$15="$500K"),"⚠ Enter $500K XS rate above","")
A24: Unlimited | B24: 1 | C24: =$B$25 -> 1.108 | D24: No per-claim cap; $1M basis = 1.000; $2M basis = XS $2M/$1M factor above
A25: ISO XS Additional Factor (XS $2M / $1M Layer) | B25: 1.108 | D25: Source: KB carrier filing (Hartford/ISO); used to auto-calc $2M occ. limit rates in col C above
A26: Selected ISO XS Rate (→ used by Indication) | B26: =IF($B$6="$2MM/$4MM",IFERROR(VLOOKUP($B$15,$A$21:$C$24,3,0),1),IFERROR(VLOOKUP($B$15,$A$21:$C$24,2,0),1)) -> 1.495
A27: Numeric Loss Limit (→ used by LossRun) | B27: =IF(B15="Unlimited",9999999999,IF(B15="$100K",100000,IF(B15="$250K",250000,IF(B15="$500K",500000,9999999999)))) -> 100000
A28: PRICING ASSUMPTIONS
A29: Annual Loss Trend Rate | B29: 0
A30: Target Loss Ratio | B30: 0.6
A31: Competing Loss Cost (per $1,000 Sales) | B31: =IFERROR(C37*B30*1000/B37,0) -> 2.533231 | C31: ← auto-derived from competing premium, target LR, and most recent AY sales
A32: BF A-priori Loss Cost (per $1,000 Sales) | B32: =IFERROR(ROUND(B9*B30/B8*1000,4),0) -> 2.5332 | C32: ← Auto-derived from Competing Premium × Target LR ÷ Prospective Sales. Override with ISO ($1.5), Hartford ($1.9), or your own estimate.
A33: (Referral triggers, credibility flags, and AY instructions are in the Indication sheet.)
A34: ANNUAL PREMIUM & SALES BY ACCIDENT YEAR
A35: Assumes 5% annual growth for sales and premium unless changed. Use [+] at left margin to expand and enter actual values.
A36: Accident Year | B36: Annual Sales ($) | C36: GL Premium ($)
A37: =IF(MONTH(IF($B$7="",TODAY(),$B$7))>=7,YEAR(IF($B$7="",TODAY(),$B$7)),YEAR(IF($B$7="",TODAY(),$B$7))-1) -> 2025 | B37: =IFERROR($B$8/1.05,0) -> 42633301 | C37: =IFERROR($B$9/1.05,0) -> 180000
A38: =A37-1 -> 2024 | B38: =IFERROR(B37/1.05,0) -> 40603144 | C38: =IFERROR(C37/1.05,0) -> 171428.57
A39: =A38-1 -> 2023 | B39: =IFERROR(B38/1.05,0) -> 38669661 | C39: =IFERROR(C38/1.05,0) -> 163265.31
A40: =A39-1 -> 2022 | B40: =IFERROR(B39/1.05,0) -> 36828248 | C40: =IFERROR(C39/1.05,0) -> 155490.77
A41: =A40-1 -> 2021 | B41: =IFERROR(B40/1.05,0) -> 35074522 | C41: =IFERROR(C40/1.05,0) -> 148086.45
A42: =A41-1 -> 2020 | B42: =IFERROR(B41/1.05,0) -> 33404307 | C42: =IFERROR(C41/1.05,0) -> 141034.71
A43: =A42-1 -> 2019 | B43: =IFERROR(B42/1.05,0) -> 31813626 | C43: =IFERROR(C42/1.05,0) -> 134318.77
...

Sheet LossRun
A1: LOSS RUN DATA — Enter Loss Date, Case Incurred, and (optional) Valuation Date
A2: Loss Date (MM/DD/YYYY) | B2: Case Incurred Loss ($) | C2: Valuation Date (MM/DD/YYYY — optional) | D2: Accident Year (auto) | E2: =IF(Setup!$B$10=0,"Net Capped Loss ($)"&CHAR(10)&"(auto · limited to "&Setup!$B$15&")","Net Capped Loss ($)"&CHAR(10)&"(auto · net of $"&TEXT(Setup!$B$10,"#,##0")&" ded."&CHAR(10)&"limited to "&Setup!$B$15&")") -> Net Capped Loss ($) (auto · net of $10,000 ded. limited to $100K) | F2: =IF(Setup!$B$10=0,"Case Incurred Loss ($)"&CHAR(10)&"(same as col B — ground-up)","Net Unlimited Loss ($)"&CHAR(10)&"(auto · gross minus "&TEXT(Setup!$B$10,"$#,##0")&" ded.)") -> Net Unlimited Loss ($) (auto · gross minus $10,000 ded.)
A3: 45926 | B3: 27000 | C3: 46112 | D3: =IF(A3="","",YEAR(A3)) -> 2025 | E3: =IF(OR(A3="",B3=""),"",MAX(0,MIN(B3,Setup!$B$27+Setup!$B$10)-Setup!$B$10)) -> 17000 | F3: =IF(OR(A3="",B3=""),"",MAX(0,B3-Setup!$B$10)) -> 17000
A4: 45646 | B4: 25000 | D4: =IF(A4="","",YEAR(A4)) -> 2024 | E4: =IF(OR(A4="",B4=""),"",MAX(0,MIN(B4,Setup!$B$27+Setup!$B$10)-Setup!$B$10)) -> 15000 | F4: =IF(OR(A4="",B4=""),"",MAX(0,B4-Setup!$B$10)) -> 15000
A5: 45516 | B5: 3438.15 | D5: =IF(A5="","",YEAR(A5)) -> 2024 | E5: =IF(OR(A5="",B5=""),"",MAX(0,MIN(B5,Setup!$B$27+Setup!$B$10)-Setup!$B$10)) -> 0 | F5: =IF(OR(A5="",B5=""),"",MAX(0,B5-Setup!$B$10)) -> 0
A6: 45544 | B6: 2170.15 | D6: =IF(A6="","",YEAR(A6)) -> 2024 | E6: =IF(OR(A6="",B6=""),"",MAX(0,MIN(B6,Setup!$B$27+Setup!$B$10)-Setup!$B$10)) -> 0 | F6: =IF(OR(A6="",B6=""),"",MAX(0,B6-Setup!$B$10)) -> 0
A7: 45502 | B7: 275000 | D7: =IF(A7="","",YEAR(A7)) -> 2024 | E7: =IF(OR(A7="",B7=""),"",MAX(0,MIN(B7,Setup!$B$27+Setup!$B$10)-Setup!$B$10)) -> 100000 | F7: =IF(OR(A7="",B7=""),"",MAX(0,B7-Setup!$B$10)) -> 265000
A8: 45474 | B8: 778.46 | D8: =IF(A8="","",YEAR(A8)) -> 2024 | E8: =IF(OR(A8="",B8=""),"",MAX(0,MIN(B8,Setup!$B$27+Setup!$B$10)-Setup!$B$10)) -> 0 | F8: =IF(OR(A8="",B8=""),"",MAX(0,B8-Setup!$B$10)) -> 0
A9: 45482 | B9: 1 | D9: =IF(A9="","",YEAR(A9)) -> 2024 | E9: =IF(OR(A9="",B9=""),"",MAX(0,MIN(B9,Setup!$B$27+Setup!$B$10)-Setup!$B$10)) -> 0 | F9: =IF(OR(A9="",B9=""),"",MAX(0,B9-Setup!$B$10)) -> 0
A10: 45782 | B10: 12 | D10: =IF(A10="","",YEAR(A10)) -> 2025 | E10: =IF(OR(A10="",B10=""),"",MAX(0,MIN(B10,Setup!$B$27+Setup!$B$10)-Setup!$B$10)) -> 0 | F10: =IF(OR(A10="",B10=""),"",MAX(0,B10-Setup!$B$10)) -> 0
A11: 45443 | B11: 22000 | D11: =IF(A11="","",YEAR(A11)) -> 2024 | E11: =IF(OR(A11="",B11=""),"",MAX(0,MIN(B11,Setup!$B$27+Setup!$B$10)-Setup!$B$10)) -> 12000 | F11: =IF(OR(A11="",B11=""),"",MAX(0,B11-Setup!$B$10)) -> 12000
A12: 45309 | B12: 1908.29 | D12: =IF(A12="","",YEAR(A12)) -> 2024 | E12: =IF(OR(A12="",B12=""),"",MAX(0,MIN(B12,Setup!$B$27+Setup!$B$10)-Setup!$B$10)) -> 0 | F12: =IF(OR(A12="",B12=""),"",MAX(0,B12-Setup!$B$10)) -> 0
A13: 44804 | B13: 4000 | D13: =IF(A13="","",YEAR(A13)) -> 2022 | E13: =IF(OR(A13="",B13=""),"",MAX(0,MIN(B13,Setup!$B$27+Setup!$B$10)-Setup!$B$10)) -> 0 | F13: =IF(OR(A13="",B13=""),"",MAX(0,B13-Setup!$B$10)) -> 0
A14: 44708 | B14: 1838.15 | D14: =IF(A14="","",YEAR(A14)) -> 2022 | E14: =IF(OR(A14="",B14=""),"",MAX(0,MIN(B14,Setup!$B$27+Setup!$B$10)-Setup!$B$10)) -> 0 | F14: =IF(OR(A14="",B14=""),"",MAX(0,B14-Setup!$B$10)) -> 0
A15: 44592 | B15: 120 | D15: =IF(A15="","",YEAR(A15)) -> 2022 | E15: =IF(OR(A15="",B15=""),"",MAX(0,MIN(B15,Setup!$B$27+Setup!$B$10)-Setup!$B$10)) -> 0 | F15: =IF(OR(A15="",B15=""),"",MAX(0,B15-Setup!$B$10)) -> 0
... A20: 44131 | B20: 1704.53 | D20: =IF(A20="","",YEAR(A20)) -> 2020 | E20: =IF(OR(A20="",B20=""),"",MAX(0,MIN(B20,Setup!$B$27+Setup!$B$10)-Setup!$B$10)) -> 0 | F20: =IF(OR(A20="",B20=""),"",MAX(0,B20-Setup!$B$10)) -> 0
D21: =IF(A21="","",YEAR(A21)) | E21: =IF(OR(A21="",B21=""),"",MAX(0,MIN(B21,Setup!$B$27+Setup!$B$10)-Setup!$B$10)) | F21: =IF(OR(A21="",B21=""),"",MAX(0,B21-Setup!$B$10))
D22: =IF(A22="","",YEAR(A22)) | E22: =IF(OR(A22="",B22=""),"",MAX(0,MIN(B22,Setup!$B$27+Setup!$B$10)-Setup!$B$10)) | F22: =IF(OR(A22="",B22=""),"",MAX(0,B22-Setup!$B$10))
D23: =IF(A23="","",YEAR(A23)) | E23: =IF(OR(A23="",B23=""),"",MAX(0,MIN(B23,Setup!$B$27+Setup!$B$10)-Setup!$B$10)) | F23: =IF(OR(A23="",B23=""),"",MAX(0,B23-Setup!$B$10))
D24: =IF(A24="","",YEAR(A24)) | E24: =IF(OR(A24="",B24=""),"",MAX(0,MIN(B24,Setup!$B$27+Setup!$B$10)-Setup!$B$10)) | F24: =IF(OR(A24="",B24=""),"",MAX(0,B24-Setup!$B$10))
D25: =IF(A25="","",YEAR(A25)) | E25: =IF(OR(A25="",B25=""),"",MAX(0,MIN(B25,Setup!$B$27+Setup!$B$10)-Setup!$B$10)) | F25: =IF(OR(A25="",B25=""),"",MAX(0,B25-Setup!$B$10))
D26: =IF(A26="","",YEAR(A26)) | E26: =IF(OR(A26="",B26=""),"",MAX(0,MIN(B26,Setup!$B$27+Setup!$B$10)-Setup!$B$10)) | F26: =IF(OR(A26="",B26=""),"",MAX(0,B26-Setup!$B$10))
D27: =IF(A27="","",YEAR(A27)) | E27: =IF(OR(A27="",B27=""),"",MAX(0,MIN(B27,Setup!$B$27+Setup!$B$10)-Setup!$B$10)) | F27: =IF(OR(A27="",B27=""),"",MAX(0,B27-Setup!$B$10))
D28: =IF(A28="","",YEAR(A28)) | E28: =IF(OR(A28="",B28=""),"",MAX(0,MIN(B28,Setup!$B$27+Setup!$B$10)-Setup!$B$10)) | F28: =IF(OR(A28="",B28=""),"",MAX(0,B28-Setup!$B$10))
D29: =IF(A29="","",YEAR(A29)) | E29: =IF(OR(A29="",B29=""),"",MAX(0,MIN(B29,Setup!$B$27+Setup!$B$10)-Setup!$B$10)) | F29: =IF(OR(A29="",B29=""),"",MAX(0,B29-Setup!$B$10))
D30: =IF(A30="","",YEAR(A30)) | E30: =IF(OR(A30="",B30=""),"",MAX(0,MIN(B30,Setup!$B$27+Setup!$B$10)-Setup!$B$10)) | F30: =IF(OR(A30="",B30=""),"",MAX(0,B30-Setup!$B$10))
D31: =IF(A31="","",YEAR(A31)) | E31: =IF(OR(A31="",B31=""),"",MAX(0,MIN(B31,Setup!$B$27+Setup!$B$10)-Setup!$B$10)) | F31: =IF(OR(A31="",B31=""),"",MAX(0,B31-Setup!$B$10))
D32: =IF(A32="","",YEAR(A32)) | E32: =IF(OR(A32="",B32=""),"",MAX(0,MIN(B32,Setup!$B$27+Setup!$B$10)-Setup!$B$10)) | F32: =IF(OR(A32="",B32=""),"",MAX(0,B32-Setup!$B$10))
... D1002: =IF(A1002="","",YEAR(A1002)) | E1002: =IF(OR(A1002="",B1002=""),"",MAX(0,MIN(B1002,Setup!$B$27+Setup!$B$10)-Setup!$B$10)) | F1002: =IF(OR(A1002="",B1002=""),"",MAX(0,B1002-Setup!$B$10))

Sheet Indication
A1: GL RATE INDICATION — Chain Ladder & Bornhuetter-Ferguson
A2: =Setup!B4 -> BDE FLORIDA | F2: =Setup!B6 -> $1MM/$2MM | J2: ="Valuation Date: "&TEXT(Setup!B7,"MM/DD/YYYY") -> Valuation Date: 04/03/2026
A4: To add accident years: insert a row above the CL Totals row and copy formulas from the row above — all aggregate calculations (indication, loss costs, referral triggers) auto-adjust. Optionally insert a matching row in the KB display section and Deductible section for per-AY detail; those totals also auto-adjust.
A5: Maturity (Months) | B5: Accident Year | C5: Annual Sales ($) | D5: =IF(Setup!$B$10=0,"Case Incurred"&CHAR(10)&"Unlimited ($)","Net Unlimited"&CHAR(10)&"Loss ($)") -> Net Unlimited Loss ($) | E5: =IF(Setup!$B$10=0,"Case Incurred"&CHAR(10)&"Capped ($)","Net Capped"&CHAR(10)&"Loss ($)") -> Net Capped Loss ($) | F5: Loss Dev. Factor | G5: % Claims Reported | H5: Expected Ultimate ($) | I5: CL Ultimate Uncapped ($) | J5: CL Ult. Capped/Unlim | K5: BF Ultimate Uncapped ($) | L5: BF Ult. Capped/Unlim | M5: Trend Years | N5: Trend Factor | O5: CL Trended Uncapped ($) | P5: CL Trended Capped ($) | Q5: BF Trended Uncapped ($) | R5: BF Trended Capped ($)
A6: =(IF(Setup!$B$7="",TODAY(),Setup!$B$7)-DATE(B6,1,1))/30.44 -> 63.009198 | B6: =IF(MONTH(IF(Setup!$B$7="",TODAY(),Setup!$B$7))>=7,YEAR(IF(Setup!$B$7="",TODAY(),Setup!$B$7)),YEAR(IF(Setup!$B$7="",TODAY(),Setup!$B$7))-1)-4 -> 2021 | C6: =IFERROR(VLOOKUP(B6,Setup!$A$37:$B$46,2,0),0) -> 35074522 | D6: =SUMIF(LossRun!$D:$D,B6,LossRun!$F:$F) -> 0 | E6: =SUMIF(LossRun!$D:$D,B6,LossRun!$E:$E) -> 0 | F6: =IF(Setup!$B$12="Everspan Fitted",EXP(Ref!$B$12*A6+Ref!$B$13)+1,EXP(Ref!$B$32*A6+Ref!$B$33)+1) -> 1.0575506 | G6: =1/F6 -> 0.94558127 | H6: =IFERROR(VLOOKUP(B6,Setup!$A$37:$C$46,3,0)*Setup!$B$30,0) -> 88851.867 | I6: =D6*F6 -> 0 | J6: =E6*F6*Setup!$B$26 -> 0 | K6: =D6+H6*(1-G6) -> 4835.2061 | L6: =E6*Setup!$B$26+H6*(1-G6) -> 4835.2061 | M6: =(DATE(YEAR(IF(Setup!$B$7="",TODAY(),Setup!$B$7))+1,MONTH(IF(Setup!$B$7="",TODAY(),Setup!$B$7)),DAY(IF(Setup!$B$7="",TODAY(),Setup!$B$7)))-DATE(B6,7,1))/365.25 -> 5.7549624 | N6: =(1+Setup!$B$29)^M6 -> 1 | O6: =I6*N6 -> 0 | P6: =J6*N6 -> 0 | Q6: =K6*N6 -> 4835.2061 | R6: =L6*N6 -> 4835.2061
A7: =(IF(Setup!$B$7="",TODAY(),Setup!$B$7)-DATE(B7,1,1))/30.44 -> 51.018397 | B7: =B6+1 -> 2022 | C7: =IFERROR(VLOOKUP(B7,Setup!$A$37:$B$46,2,0),0) -> 36828248 | D7: =SUMIF(LossRun!$D:$D,B7,LossRun!$F:$F) -> 560386.9 | E7: =SUMIF(LossRun!$D:$D,B7,LossRun!$E:$E) -> 100000 | F7: =IF(Setup!$B$12="Everspan Fitted",EXP(Ref!$B$12*A7+Ref!$B$13)+1,EXP(Ref!$B$32*A7+Ref!$B$33)+1) -> 1.1251583 | G7: =1/F7 -> 0.88876384 | H7: =IFERROR(VLOOKUP(B7,Setup!$A$37:$C$46,3,0)*Setup!$B$30,0) -> 93294.461 | I7: =D7*F7 -> 630523.97 | J7: =E7*F7*Setup!$B$26 -> 168211.16 | K7: =D7+H7*(1-G7) -> 570764.62 | L7: =E7*Setup!$B$26+H7*(1-G7) -> 159877.72 | M7: =(DATE(YEAR(IF(Setup!$B$7="",TODAY(),Setup!$B$7))+1,MONTH(IF(Setup!$B$7="",TODAY(),Setup!$B$7)),DAY(IF(Setup!$B$7="",TODAY(),Setup!$B$7)))-DATE(B7,7,1))/365.25 -> 4.7556468 | N7: =(1+Setup!$B$29)^M7 -> 1 | O7: =I7*N7 -> 630523.97 | P7: =J7*N7 -> 168211.16 | Q7: =K7*N7 -> 570764.62 | R7: =L7*N7 -> 159877.72
A8: =(IF(Setup!$B$7="",TODAY(),Setup!$B$7)-DATE(B8,1,1))/30.44 -> 39.027595 | B8: =B7+1 -> 2023 | C8: =IFERROR(VLOOKUP(B8,Setup!$A$37:$B$46,2,0),0) -> 38669661 | D8: =SUMIF(LossRun!$D:$D,B8,LossRun!$F:$F) -> 0 | E8: =SUMIF(LossRun!$D:$D,B8,LossRun!$E:$E) -> 0 | F8: =IF(Setup!$B$12="Everspan Fitted",EXP(Ref!$B$12*A8+Ref!$B$13)+1,EXP(Ref!$B$32*A8+Ref!$B$33)+1) -> 1.2721884 | G8: =1/F8 -> 0.78604707 | H8: =IFERROR(VLOOKUP(B8,Setup!$A$37:$C$46,3,0)*Setup!$B$30,0) -> 97959.184 | I8: =D8*F8 -> 0 | J8: =E8*F8*Setup!$B$26 -> 0 | K8: =D8+H8*(1-G8) -> 20958.654 | L8: =E8*Setup!$B$26+H8*(1-G8) -> 20958.654 | M8: =(DATE(YEAR(IF(Setup!$B$7="",TODAY(),Setup!$B$7))+1,MONTH(IF(Setup!$B$7="",TODAY(),Setup!$B$7)),DAY(IF(Setup!$B$7="",TODAY(),Setup!$B$7)))-DATE(B8,7,1))/365.25 -> 3.7563313 | N8: =(1+Setup!$B$29)^M8 -> 1 | O8: =I8*N8 -> 0 | P8: =J8*N8 -> 0 | Q8: =K8*N8 -> 20958.654 | R8: =L8*N8 -> 20958.654
A9: =(IF(Setup!$B$7="",TODAY(),Setup!$B$7)-DATE(B9,1,1))/30.44 -> 27.036794 | B9: =B8+1 -> 2024 | C9: =IFERROR(VLOOKUP(B9,Setup!$A$37:$B$46,2,0),0) -> 40603144 | D9: =SUMIF(LossRun!$D:$D,B9,LossRun!$F:$F) -> 292000 | E9: =SUMIF(LossRun!$D:$D,B9,LossRun!$E:$E) -> 127000 | F9: =IF(Setup!$B$12="Everspan Fitted",EXP(Ref!$B$12*A9+Ref!$B$13)+1,EXP(Ref!$B$32*A9+Ref!$B$33)+1) -> 1.5919428 | G9: =1/F9 -> 0.62816327 | H9: =IFERROR(VLOOKUP(B9,Setup!$A$37:$C$46,3,0)*Setup!$B$30,0) -> 102857.14 | I9: =D9*F9 -> 464847.3 | J9: =E9*F9*Setup!$B$26 -> 302254.22 | K9: =D9+H9*(1-G9) -> 330246.06 | L9: =E9*Setup!$B$26+H9*(1-G9) -> 228111.06 | M9: =(DATE(YEAR(IF(Setup!$B$7="",TODAY(),Setup!$B$7))+1,MONTH(IF(Setup!$B$7="",TODAY(),Setup!$B$7)),DAY(IF(Setup!$B$7="",TODAY(),Setup!$B$7)))-DATE(B9,7,1))/365.25 -> 2.7542779 | N9: =(1+Setup!$B$29)^M9 -> 1 | O9: =I9*N9 -> 464847.3 | P9: =J9*N9 -> 302254.22 | Q9: =K9*N9 -> 330246.06 | R9: =L9*N9 -> 228111.06
A10: =(IF(Setup!$B$7="",TODAY(),Setup!$B$7)-DATE(B10,1,1))/30.44 -> 15.013141 | B10: =B9+1 -> 2025 | C10: =IFERROR(VLOOKUP(B10,Setup!$A$37:$B$46,2,0),0) -> 42633301 | D10: =SUMIF(LossRun!$D:$D,B10,LossRun!$F:$F) -> 17000 | E10: =SUMIF(LossRun!$D:$D,B10,LossRun!$E:$E) -> 17000 | F10: =IF(Setup!$B$12="Everspan Fitted",EXP(Ref!$B$12*A10+Ref!$B$13)+1,EXP(Ref!$B$32*A10+Ref!$B$33)+1) -> 2.2900728 | G10: =1/F10 -> 0.43666735 | H10: =IFERROR(VLOOKUP(B10,Setup!$A$37:$C$46,3,0)*Setup!$B$30,0) -> 108000 | I10: =D10*F10 -> 38931.237 | J10: =E10*F10*Setup!$B$26 -> 58202.2 | K10: =D10+H10*(1-G10) -> 77839.927 | L10: =E10*Setup!$B$26+H10*(1-G10) -> 86254.927 | M10: =(DATE(YEAR(IF(Setup!$B$7="",TODAY(),Setup!$B$7))+1,MONTH(IF(Setup!$B$7="",TODAY(),Setup!$B$7)),DAY(IF(Setup!$B$7="",TODAY(),Setup!$B$7)))-DATE(B10,7,1))/365.25 -> 1.7549624 | N10: =(1+Setup!$B$29)^M10 -> 1 | O10: =I10*N10 -> 38931.237 | P10: =J10*N10 -> 58202.2 | Q10: =K10*N10 -> 77839.927 | R10: =L10*N10 -> 86254.927
B11: Totals | C11: =SUM(C6:C10) -> 1.9380888e+08 | D11: =SUM(D6:D10) -> 869386.9 | E11: =SUM(E6:E10) -> 244000 | H11: =SUM(H6:H10) -> 490962.65 | I11: =SUM(I6:I10) -> 1134302.5 | J11: =SUM(J6:J10) -> 528667.58 | K11: =SUM(K6:K10) -> 1004644.5 | L11: =SUM(L6:L10) -> 500037.57 | O11: =SUM(O6:O10) -> 1134302.5 | P11: =SUM(P6:P10) -> 528667.58 | Q11: =SUM(Q6:Q10) -> 1004644.5 | R11: =SUM(R6:R10) -> 500037.57
A13: ="── INDICATION ("&IF(Setup!$B$29=0,"No Trend Applied",TEXT(Setup!$B$29,"0.0%")&" Annual Trend")&") ──" -> ── INDICATION (No Trend Applied) ──
A14: Blended CL Trended Ultimate (Capped/Uncapped Weighted) | F14: =Setup!$B$16*P11+(1-Setup!$B$16)*O11 -> 831485.04
A15: Blended BF Trended Ultimate (Capped/Uncapped Weighted) | F15: =Setup!$B$16*R11+(1-Setup!$B$16)*Q11 -> 752341.02
A16: Final Blended Trended Ultimate (CL/BF Weighted) | F16: =Setup!$B$17*F14+(1-Setup!$B$17)*F15 -> 791913.03
A17: Final Blended Ultimate (Untrended — for reference) | F17: =Setup!$B$17*(Setup!$B$16*J11+(1-Setup!$B$16)*I11)+(1-Setup!$B$17)*(Setup!$B$16*L11+(1-Setup!$B$16)*K11) -> 791913.03
A18: Indicated Sales Rate (per $1,000 Sales) | F18: =IFERROR(F16/C11/Setup!$B$30*1000,0) -> 6.8100857
A19: HH Indicated Annual Premium | F19: =IFERROR(F18*Setup!$B$8/1000,0) -> 304853.25
A21: ── INDICATION ──
A22: Maturity of Claims (Months) | B22: Accident Year | C22: Total Annual Sales ($) | D22: =IF(Setup!$B$10=0,"Case Incurred"&CHAR(10)&"Unlimited ($)","Net Unlimited"&CHAR(10)&"Loss ($)") -> Net Unlimited Loss ($) | E22: =IF(Setup!$B$10=0,"Case Incurred"&CHAR(10)&"Capped to "&Setup!$B$15&CHAR(10)&"($)","Net Capped"&CHAR(10)&"(ded.+limit) ($)") -> Net Capped (ded.+limit) ($) | F22: Loss Development Factor | G22: % Claims Reported | H22: Expected Loss ($) | I22: Ultimate (Uncapped) | J22: Ultimate (Capped) ($) | K22: Loss Cost (Uncapped) | L22: Loss Cost (Capped)
A23: =A6 -> 63.009198 | B23: =B6 -> 2021 | C23: =C6 -> 35074522 | D23: =D6 -> 0 | E23: =E6 -> 0 | F23: =F6 -> 1.0575506 | G23: =G6 -> 0.94558127 | H23: =H6 -> 88851.867 | I23: =K6 -> 4835.2061 | J23: =L6 -> 4835.2061 | K23: =IFERROR(I23/C23*1000,0) -> 0.13785522 | L23: =IFERROR(J23/C23*1000,0) -> 0.13785522
A24: =A7 -> 51.018397 | B24: =B7 -> 2022 | C24: =C7 -> 36828248 | D24: =D7 -> 560386.9 | E24: =E7 -> 100000 | F24: =F7 -> 1.1251583 | G24: =G7 -> 0.88876384 | H24: =H7 -> 93294.461 | I24: =K7 -> 570764.62 | J24: =L7 -> 159877.72 | K24: =IFERROR(I24/C24*1000,0) -> 15.498012 | L24: =IFERROR(J24/C24*1000,0) -> 4.3411708
A25: =A8 -> 39.027595 | B25: =B8 -> 2023 | C25: =C8 -> 38669661 | D25: =D8 -> 0 | E25: =E8 -> 0 | F25: =F8 -> 1.2721884 | G25: =G8 -> 0.78604707 | H25: =H8 -> 97959.184 | I25: =K8 -> 20958.654 | J25: =L8 -> 20958.654 | K25: =IFERROR(I25/C25*1000,0) -> 0.5419922 | L25: =IFERROR(J25/C25*1000,0) -> 0.5419922
A26: =A9 -> 27.036794 | B26: =B9 -> 2024 | C26: =C9 -> 40603144 | D26: =D9 -> 292000 | E26: =E9 -> 127000 | F26: =F9 -> 1.5919428 | G26: =G9 -> 0.62816327 | H26: =H9 -> 102857.14 | I26: =K9 -> 330246.06 | J26: =L9 -> 228111.06 | K26: =IFERROR(I26/C26*1000,0) -> 8.1335097 | L26: =IFERROR(J26/C26*1000,0) -> 5.6180641
A27: =A10 -> 15.013141 | B27: =B10 -> 2025 | C27: =C10 -> 42633301 | D27: =D10 -> 17000 | E27: =E10 -> 17000 | F27: =F10 -> 2.2900728 | G27: =G10 -> 0.43666735 | H27: =H10 -> 108000 | I27: =K10 -> 77839.927 | J27: =L10 -> 86254.927 | K27: =IFERROR(I27/C27*1000,0) -> 1.8258011 | L27: =IFERROR(J27/C27*1000,0) -> 2.023182
B28: Totals | C28: =C11 -> 1.9380888e+08 | D28: =D11 -> 869386.9 | E28: =E11 -> 244000 | H28: =H11 -> 490962.65 | I28: =K11 -> 1004644.5 | J28: =L11 -> 500037.57 | K28: =IFERROR(K11/C11*1000,0) -> 5.1836866 | L28: =IFERROR(L11/C11*1000,0) -> 2.580055
A30: ISO XS Rate (Selected Limit → Unlimited) | B30: =Setup!$B$26 -> 1.495 | D30: ISO XS $2M / $1M | E30: =Setup!$B$25 -> 1.108
A31: Competing Loss Cost (per $1,000 Sales) | B31: =IFERROR(Ref!B38,0) -> 2.533231 | D31: Target Loss Ratio | E31: =Setup!$B$30 -> 0.6
A32: Indicated Loss Cost (Weighted, per $1,000 Sales) | B32: =IFERROR(Setup!$B$16*(J28/C28*1000)+(1-Setup!$B$16)*(I28/C28*1000),0) -> 3.8818708 | D32: Capped / Uncapped Weighting | E32: =Setup!$B$16 -> 0.5
A33: Indicated Rate (per $1,000 Sales) | B33: =IFERROR(B32/Setup!$B$30,0) -> 6.4697847 | D33: Prospective Annual Sales | E33: =Setup!$B$8 -> 44764966
A34: KB Premium Indication | B34: =IFERROR(MAX(B33*Setup!$B$8/1000,Setup!$B$9*0.9),0) -> 289619.69
A35: Premium Indication | B35: =IFERROR(B33*Setup!$B$8/1000,0) -> 289619.69
A36: Selected Premium | B36: 290000
A37: Expected Loss Ratio | B37: =IFERROR(B32*Setup!$B$8/1000/B36,0) -> 0.59921315
A38: Indication Basis | F38: =IF(Setup!$B$10=0,"Ground-Up (No Deductible)","Net of $"&TEXT(Setup!$B$10,"#,##0")&" per Occ. Deductible") -> Net of $10,000 per Occ. Deductible
A39: ── REFERRAL TRIGGERS ──
A40: KB vs. HH Premium Variance (CL-Only vs. CL/BF Blend) | F40: =IFERROR(B35/F19-1,0) -> -0.049970149 | G40: =IF(D11=0,"-",IFERROR(IF(ABS(F40)>0.15,"REFER — variance > 15%","IN RANGE"),"-")) -> IN RANGE
A41: Large Loss Influence (net ultimate − net capped) / net unlimited | F41: =IF(D11=0,"-",IF((D11-E11)/D11>0.5,"REFER — large loss > 50% of total","OK TO BIND")) -> REFER — large loss > 50% of total
A42: Age of Loss Runs | F42: =IFERROR(IF(DATEDIF(Setup!$B$7,TODAY(),"M")>6,"REFER — "&DATEDIF(Setup!$B$7,TODAY(),"M")&" months since val date; request fresh loss runs",DATEDIF(Setup!$B$7,TODAY(),"M")&" months since valuation date"),"-") -> 1 months since valuation date
A43: Claim Data Credibility | F43: =IF(COUNTA(LossRun!$A$3:$A$1002)=0,"-",IF(COUNTA(LossRun!$A$3:$A$1002)<5,"REFER — fewer than 5 claims",IF(COUNTIF(OFFSET($D$6,0,0,ROW($D$11)-ROW($D$6),1),0)>0,"REFER — AY with zero losses","OK TO BIND"))) -> REFER — AY with zero losses
A44: Competing Premium vs. HH Indicated (>±15% = REFER) — ensure Competing Premium in Setup is NET of deductible when applicable | F44: =IFERROR(IF(ABS(Setup!$B$9/F19-1)>0.15,"REFER — review premium adequacy","OK TO BIND"),"-") -> REFER — review premium adequacy
...

Sheet EXPORT
A1: NAMED INSURED | B1: ADDRESS | C1: SALES | D1: SQUARE FOOTAGE | E1: EMPLOYEES
A2: =SOV!A1 -> BDE Florida, LLC | B2: =_xlfn.CONCAT(SOV!C4,", ",SOV!D4,", ",SOV!E4," ",SOV!F4) -> 3401 5th Ave. N, St. Petersburg, FL 33713 | C2: =SOV!N4 -> 2102629 | D2: =SOV!Q4 -> 2780 | E2: 35
B3: =_xlfn.CONCAT(SOV!C5,", ",SOV!D5,", ",SOV!E5," ",SOV!F5) -> 7329 W. Waters Ave., Tampa, FL 33634 | C3: =SOV!N5 -> 1645087 | D3: =SOV!Q5 -> 2182 | E3: 35
B4: =_xlfn.CONCAT(SOV!C6,", ",SOV!D6,", ",SOV!E6," ",SOV!F6) -> 5318 E. Fowler Ave., Tampa, FL 33617 | C4: =SOV!N6 -> 2080081 | D4: =SOV!Q6 -> 2599 | E4: 35
B5: =_xlfn.CONCAT(SOV!C7,", ",SOV!D7,", ",SOV!E7," ",SOV!F7) -> 3600 4th St. N, St. Petersburg, FL 33704 | C5: =SOV!N7 -> 1675024 | D5: =SOV!Q7 -> 2304 | E5: 35
B6: =_xlfn.CONCAT(SOV!C8,", ",SOV!D8,", ",SOV!E8," ",SOV!F8) -> 904 Bloomingdale Rd., Brandon, FL 33511 | C6: =SOV!N8 -> 1092838 | D6: =SOV!Q8 -> 1944 | E6: 35
B7: =_xlfn.CONCAT(SOV!C9,", ",SOV!D9,", ",SOV!E9," ",SOV!F9) -> 7313 Gall Blvd., Zephyrhills, FL 33541 | C7: =SOV!N9 -> 2955757 | D7: =SOV!Q9 -> 1944 | E7: 35
B8: =_xlfn.CONCAT(SOV!C10,", ",SOV!D10,", ",SOV!E10," ",SOV!F10) -> 706 E. Martin Luther King Jr Blvd. W, Seffner, FL 33584 | C8: =SOV!N10 -> 2250722 | D8: =SOV!Q10 -> 1980 | E8: 35
B9: =_xlfn.CONCAT(SOV!C11,", ",SOV!D11,", ",SOV!E11," ",SOV!F11) -> 1701 E. Fowler Ave., Tampa, FL 33612 | C9: =SOV!N11 -> 1249150 | D9: =SOV!Q11 -> 2304 | E9: 35
B10: =_xlfn.CONCAT(SOV!C12,", ",SOV!D12,", ",SOV!E12," ",SOV!F12) -> 3802 S. Dale Mabry Hwy., Tampa, FL 33611 | C10: =SOV!N12 -> 2097026 | D10: =SOV!Q12 -> 2394 | E10: 35
B11: =_xlfn.CONCAT(SOV!C13,", ",SOV!D13,", ",SOV!E13," ",SOV!F13) -> 3710 Cortez Rd. W, Bradenton, FL 34210 | C11: =SOV!N13 -> 1885914 | D11: =SOV!Q13 -> 2166 | E11: 35
B12: =_xlfn.CONCAT(SOV!C14,", ",SOV!D14,", ",SOV!E14," ",SOV!F14) -> 7620 W. Hillsborough Ave., Tampa, FL 33615 | C12: =SOV!N14 -> 1338151 | D12: =SOV!Q14 -> 2304 | E12: 35
B13: =_xlfn.CONCAT(SOV!C15,", ",SOV!D15,", ",SOV!E15," ",SOV!F15) -> 6004 14th St., Bradenton, FL 34207 | C13: =SOV!N15 -> 2029898 | D13: =SOV!Q15 -> 2060 | E13: 35
B14: =_xlfn.CONCAT(SOV!C16,", ",SOV!D16,", ",SOV!E16," ",SOV!F16) -> 11315 Causeway Blvd., Brandon, FL 33511 | C14: =SOV!N16 -> 2265453 | D14: =SOV!Q16 -> 2062 | E14: 35
... B28: =_xlfn.CONCAT(SOV!C30,", ",SOV!D30,", ",SOV!E30," ",SOV!F30) -> 3824 US 301 S, Riverview, FL 33578 | C28: =SOV!N30 -> 1500000 | D28: =SOV!Q30 -> 2200 | E28: 35

Sheet Umbrella
A1: MAINSTREET UMBRELLA INDICATION — $5M Excess Facility (Authentic / Builders)
A3: INPUTS
A4: Account Name | B4: =Setup!B4 -> BDE FLORIDA | C4: ← from Setup!B4
A6: Attachment Point (=Underlying GL Limits) | B6: =Setup!B6 -> $1MM/$2MM | C6: ← First-$5M program follows underlying. Pulls from Setup!B6.
A7: Hazard Tier (UW Manager assigns) | B7: Medium | C7: ← Required: Medium / High (Low not used per Mainstreet guidelines)
A8: Schedule / Judgment Mod | B8: 1 | C8: ← Default 1.00. Range 0.75-1.25 in 0.05 steps. UW Manager adjusts.
A10: Underlying GL Primary Premium (Auto-Pull) | B10: =IF(Indication!B36>0,Indication!B36,Indication!B35) -> 290000 | C10: ← Auto: Selected Premium (B36) if entered; else CL-Only Premium Indication (B35)
A12: Underlying Premium Used | B12: =B10 -> 290000 | C12: ← Same as B10. Drives the umbrella calc. Premium = Underlying x (ILF - Attach Factor) x Sched Mod
A13: ** KEY ASSUMPTION: The umbrella premium is computed as a load on the UNDERLYING PRIMARY GL PREMIUM. Auto-pull at B10 reads Indication!B36 (Selected Premium) if non-zero, else falls back to Indication!B35 (CL-Only Premium Indication). If quoting excess over a different primary, enter that figure directly in Indication!B36 (Selected Premium) and it will flow through here. Mis-set this and the umbrella quote will be off proportionally.
A14: For reference - Selected Premium (Indication!B36) | B14: =Indication!B36 -> 290000
A15: For reference - CL-Only Premium Indication (Indication!B35, default fallback) | B15: =Indication!B35 -> 289619.69
A16: For reference - KB CL-Only with 90%-of-expiring floor (Indication!B34) | B16: =Indication!B34 -> 289619.69
A17: For reference - HH Blended Indication (Indication!F19) | B17: =Indication!F19 -> 304853.25
A18: LADDERED UMBRELLA QUOTES (per layer over selected attachment) — Min Premium column is CUMULATIVE (stacks prior layer minimums)
A19: Umbrella Limit | B19: ILF Factor | C19: Attach Factor | D19: Calc'd Premium | E19: Min Premium | F19: FINAL PREMIUM | G19: Load % (of underlying)
A20: 1000000 | B20: =INDEX($G$31:$H$35,MATCH(A20,$F$31:$F$35,0),MATCH($B$7,$G$30:$H$30,0)) -> 0.144 | C20: =VLOOKUP($B$6,$F$39:$G$40,2,FALSE()) -> 0.02 | D20: =$B$12*(B20-C20)*$B$8 -> 35960 | E20: =SUM(INDEX($G$44:$H$48,1,MATCH($B$7,$G$43:$H$43,0)):INDEX($G$44:$H$48,MATCH($A20,$F$44:$F$48,0),MATCH($B$7,$G$43:$H$43,0))) -> 1000 | F20: =MAX(D20,E20) -> 35960 | G20: =IFERROR(F20/$B$12,0) -> 0.124
A21: 2000000 | B21: =INDEX($G$31:$H$35,MATCH(A21,$F$31:$F$35,0),MATCH($B$7,$G$30:$H$30,0)) -> 0.218 | C21: =VLOOKUP($B$6,$F$39:$G$40,2,FALSE()) -> 0.02 | D21: =$B$12*(B21-C21)*$B$8 -> 57420 | E21: =SUM(INDEX($G$44:$H$48,1,MATCH($B$7,$G$43:$H$43,0)):INDEX($G$44:$H$48,MATCH($A21,$F$44:$F$48,0),MATCH($B$7,$G$43:$H$43,0))) -> 1500 | F21: =MAX(D21,E21) -> 57420 | G21: =IFERROR(F21/$B$12,0) -> 0.198
A22: 3000000 | B22: =INDEX($G$31:$H$35,MATCH(A22,$F$31:$F$35,0),MATCH($B$7,$G$30:$H$30,0)) -> 0.277 | C22: =VLOOKUP($B$6,$F$39:$G$40,2,FALSE()) -> 0.02 | D22: =$B$12*(B22-C22)*$B$8 -> 74530 | E22: =SUM(INDEX($G$44:$H$48,1,MATCH($B$7,$G$43:$H$43,0)):INDEX($G$44:$H$48,MATCH($A22,$F$44:$F$48,0),MATCH($B$7,$G$43:$H$43,0))) -> 2000 | F22: =MAX(D22,E22) -> 74530 | G22: =IFERROR(F22/$B$12,0) -> 0.257
A23: 4000000 | B23: =INDEX($G$31:$H$35,MATCH(A23,$F$31:$F$35,0),MATCH($B$7,$G$30:$H$30,0)) -> 0.322 | C23: =VLOOKUP($B$6,$F$39:$G$40,2,FALSE()) -> 0.02 | D23: =$B$12*(B23-C23)*$B$8 -> 87580 | E23: =SUM(INDEX($G$44:$H$48,1,MATCH($B$7,$G$43:$H$43,0)):INDEX($G$44:$H$48,MATCH($A23,$F$44:$F$48,0),MATCH($B$7,$G$43:$H$43,0))) -> 2500 | F23: =MAX(D23,E23) -> 87580 | G23: =IFERROR(F23/$B$12,0) -> 0.302
A24: 5000000 | B24: =INDEX($G$31:$H$35,MATCH(A24,$F$31:$F$35,0),MATCH($B$7,$G$30:$H$30,0)) -> 0.362 | C24: =VLOOKUP($B$6,$F$39:$G$40,2,FALSE()) -> 0.02 | D24: =$B$12*(B24-C24)*$B$8 -> 99180 | E24: =SUM(INDEX($G$44:$H$48,1,MATCH($B$7,$G$43:$H$43,0)):INDEX($G$44:$H$48,MATCH($A24,$F$44:$F$48,0),MATCH($B$7,$G$43:$H$43,0))) -> 3000 | F24: =MAX(D24,E24) -> 99180 | G24: =IFERROR(F24/$B$12,0) -> 0.342
A25: ^ $5M = the Mainstreet umbrella facility's max capacity. Highlighted row is the headline quote.
A27: REFERENCE TABLES (Mainstreet rater factors, approved by capacity partners)
A29: Standard Exclusions / Forms (umbrella follows underlying except as noted) | F29: ILF Factor Table
A30: - ISO Excess Liability form; follows underlying primary in form and intent | F30: Limit | G30: Medium | H30: High
A31: - Construction Activities Exclusion | F31: 1000000 | G31: 0.144 | H31: 0.228
A32: - Discrimination Exclusion | F32: 2000000 | G32: 0.218 | H32: 0.362
A33: - Communicable Disease Exclusion | F33: 3000000 | G33: 0.277 | H33: 0.471
A34: - Anti-Stacking Provisions | F34: 4000000 | G34: 0.322 | H34: 0.57
A35: - Silica / Silica-Related Dust Exclusion | F35: 5000000 | G35: 0.362 | H35: 0.664
A36: - PFAS Exclusion
A37: - Absolute Pollution Exclusion | F37: Aggregate Limit Factor (attachment-point discount)
A38: - Nuclear Energy Liability Exclusion | F38: GL Limit | G38: Factor
A39: - Cannabis Exclusion (hemp exception) | F39: $1MM/$2MM | G39: 0.02
A40: - Absolute Lead Exclusion | F40: $2MM/$4MM | G40: 0.04
A41: - North American War Exclusion
A42: - Sexual Abuse & Molestation (SAM): ALWAYS EXCLUDED ON UMBRELLA (separate, sublimit, or otherwise) | F42: Updated Minimum Premium (hazard-tiered)
A43: - Liquor Liability: follows underlying - not in AL/VT/DC/AK/SC; restaurants only; <30% revenue; TIPS req'd | F43: Limit | G43: Medium | H43: High
A44: - Assault & Battery: silent unless loss-driven exclude (loss runs review) | F44: 1000000 | G44: 1000 | H44: 1500
A45: - Professional Liability: follows underlying positioning; not for restaurant classes | F45: 2000000 | G45: 500 | H45: 1000
A46: - No sublimited coverages extended on umbrella | F46: 3000000 | G46: 500 | H46: 1000
...

Sheet Ref
A1: LDF TABLES, REGRESSION PARAMETERS & BENCHMARK CALCULATIONS
A3: EVERSPAN ANNUAL LDFs (Source: Everspan Carrier Filing)
A4: Maturity (Months) | B4: ln(LDF−1) | C4: LDF — Actual | D4: LDF — Fitted
A5: 60 | B5: -2.6173 | C5: 1.073 | D5: 1.0699
A6: 48 | B6: -1.8773 | C6: 1.153 | D6: 1.1522
A7: 36 | B7: -1.1777 | C7: 1.308 | D7: 1.3312
A8: 24 | B8: -0.3696 | C8: 1.691 | D8: 1.7207
A9: 12 | B9: 0.5164 | C9: 2.676 | D9: 2.5682
A11: Regression Parameters — Everspan
A12: Slope | B12: -0.064792613
A13: Intercept | B13: 1.2274392
A15: HARTFORD QUARTERLY LDFs (Source: Hartford Carrier Filing)
A16: Maturity (Months) | B16: ln(LDF−1) | C16: LDF — Actual | D16: LDF — Fitted
A17: 3 | B17: 1.6599409 | C17: 6.259 | D17: 4.819
A18: 6 | B18: 0.95242978 | C18: 3.592 | D18: 3.847
A19: 9 | B19: 0.63073972 | C19: 2.879 | D19: 3.123
A20: 12 | B20: 0.34074879 | C20: 2.406 | D20: 2.582
A21: 15 | B21: 0.075107472 | C21: 2.078 | D21: 2.18
A22: 18 | B22: -0.17435339 | C22: 1.84 | D22: 1.879
A23: 21 | B23: -0.42617815 | C23: 1.653 | D23: 1.656
A24: 24 | B24: -0.68915516 | C24: 1.502 | D24: 1.489
A25: 27 | B25: -0.96758403 | C25: 1.38 | D25: 1.364
A26: 30 | B26: -1.2447948 | C26: 1.288 | D26: 1.272
A27: 33 | B27: -1.565421 | C27: 1.209 | D27: 1.203
A28: 36 | B28: -1.89712 | C28: 1.15 | D28: 1.151
A30: Regression Parameters — Hartford
A31: Slope | B31: -0.097905997
A32: Slope (used by Indication → Ref!B32) | B32: -0.097905997
A33: Intercept (used by Indication → Ref!B33) | B33: 1.6336969
A35: BENCHMARK RATE CALCULATIONS
A37: Method A — Competing / Expiring Premium
A38: Competing Loss Cost (per $1,000 Sales) | B38: =Setup!$B$31 -> 2.533231
A39: Benchmark GL Rate (per $1,000 Sales) [B38 / Target LR] | B39: =IFERROR(B38/Setup!$B$30,0) -> 4.2220517
A41: Method B — ISO Manual Rates
A42: ISO GL Loss Cost (per $1,000 Sales) | B42: 1.5
A43: ISO XS $1M / $100K | B43: =Setup!$B$21 -> 1.495
A44: Benchmark GL Rate (per $1,000 Sales) [B42 × ISO XS / Target LR] | B44: =IFERROR(B42*B43/Setup!$B$30,0) -> 3.7375
A46: Method C — Hartford Manual Rates
A47: Hartford GL Loss Cost (per $1,000 Sales) | B47: 1.9
A48: Benchmark GL Rate (per $1,000 Sales) [B47 / Target LR] | B48: =IFERROR(B47/Setup!$B$30,0) -> 3.1666667
...
